Workbook

Sheet Balance Sheet
B1: Balance Sheet — Microsoft Corporation (MSFT)
B2: ASSETS | C2: FY2024 (Jun 30, 2024) | D2: FY2023 (Jun 30, 2023) | F2: LIABILITIES & EQUITY | G2: FY2024 (Jun 30, 2024) | H2: FY2023 (Jun 30, 2023)
B3: (All figures in $millions) | F3: (All figures in $millions)
B4: Current Assets | F4: Current Liabilities
B5: Cash and marketable securities | C5: 75543 | D5: 111262 | F5: Debt due for repayment | G5: 8942 | H5: 5247
B6: Receivables | C6: 56924 | D6: 48688 | F6: Accounts payable | G6: 21996 | H6: 18095
B7: Inventories | C7: 1246 | D7: 2500 | F7: Other current liabilities | G7: 94348 | H7: 80807
B8: Other current assets | C8: 26021 | D8: 21807 | F8: Total current liabilities | G8: =SUM(G5:G7) -> 125286 | H8: =SUM(H5:H7) -> 104149
B9: Total current assets | C9: =SUM(C5:C8) -> 159734 | D9: =SUM(D5:D8) -> 184257
F10: Long-term debt | G10: 42688 | H10: 41990
B11: Fixed Assets | F11: Other long-term liabilities | G11: 75712 | H11: 59614
B12: Property, plant, and equipment | C12: 212012 | D12: 163892
B13: Less accumulated depreciation | C13: 76421 | D13: 68251 | F13: Total Liabilities | G13: =G8+G10+G11 -> 243686 | H13: =H8+H10+H11 -> 205753
B14: Net tangible fixed assets | C14: =C12-C13 -> 135591 | D14: =D12-D13 -> 95641
F15: Stockholders' Equity
B16: Other Assets | F16: Common stock and paid-in capital | G16: 100923 | H16: 93718
B17: Intangible assets (goodwill & intangibles) | C17: 146817 | D17: 77252 | F17: Retained earnings (incl. AOCI) | G17: 167554 | H17: 112505
B18: Other assets | C18: =G20-C9-C14-C17 -> 70021 | D18: =H20-D9-D14-D17 -> 54826 | F18: Total stockholders' equity | G18: =G16+G17 -> 268477 | H18: =H16+H17 -> 206223
B20: Total Assets | C20: =C9+C14+C17+C18 -> 512163 | D20: =D9+D14+D17+D18 -> 411976 | F20: Total Liabilities + Equity | G20: =G13+G18 -> 512163 | H20: =H13+H18 -> 411976
B21: Balance Check (TA − TL&E) | C21: =C20-G20 -> 0
B22: Source: Microsoft 10-K FY2024, SEC EDGAR

Sheet Income Statement
B1: Income Statement — Microsoft Corporation (MSFT)
B2: Line Item | C2: FY2024 (Jun 30, 2024) | D2: % of Sales
B3: (All figures in $millions)
B4: Net sales | C4: 245122 | D4: =IF(C$4=0,0,C4/C$4) -> 1
B5: less Cost of goods sold | C5: 74114 | D5: =IF(C$4=0,0,C5/C$4) -> 0.30235556
B6: less Selling, general & administrative | C6: =C4-C5 -> 171008 | D6: =IF(C$4=0,0,C6/C$4) -> 0.69764444
B7: less Depreciation & amortization | C7: 22287 | D7: 0.090922071
B8: Earnings before interest & taxes (EBIT) | C8: 109433 | D8: =IF(C$4=0,0,C8/C$4) -> 0.446443
D9: =IF(C$4=0,0,C9/C$4) -> 0
B10: plus Other income (expense), net | C10: -1646 | D10: =IF(C$4=0,0,C10/C$4) -> -0.0067150235
B11: less Interest expense | C11: 0 | D11: 0
B12: Taxable income | C12: =C8+C10-C11 -> 107787 | D12: =IF(C$4=0,0,C12/C$4) -> 0.43972797
D13: =IF(C$4=0,0,C13/C$4) -> 0
B14: less Taxes | C14: 19651 | D14: 0.080168243
B15: Net income | C15: =C12-C14 -> 88136 | D15: =IF(C$4=0,0,C15/C$4) -> 0.35955973
D16: =IF(C$4=0,0,C16/C$4) -> 0
B17: Allocation of Net Income | C17: =C15-C16 -> 88136 | D17: =IF(C$4=0,0,C17/C$4) -> 0.35955973
B18: Dividends | C18: 22296 | D18: =IF(C$4=0,0,C18/C$4) -> 0.090958788
B19: Addition to retained earnings | C19: =C17-C18 -> 65840 | D19: =IF(C$4=0,0,C19/C$4) -> 0.26860094
B21: Source: Microsoft 10-K FY2024, SEC EDGAR

Sheet Cash Flow Statement
B1: Cash Flow Statement — Microsoft Corporation (MSFT)
B2: Line Item | C2: FY2024 (Jun 30, 2024) | D2: Source / Notes
B3: (All figures in $millions)
B4: Operations:
B5: Net income | C5: 88136 | D5: [Income Statement]
B6: plus Depreciation | C6: 22287 | D6: [Income Statement]
B7: plus Changes in working capital items
B8: Decrease (increase) in accounts receivable | C8: -7191 | D8: [Balance Sheet]
B9: Decrease (increase) in inventories | C9: 1254 | D9: [Balance Sheet]
B10: Decrease (increase) in other current assets | C10: -4214 | D10: [Balance Sheet]
B11: Increase (decrease) in accounts payable | C11: 3901 | D11: [Balance Sheet]
B12: Increase (decrease) in other current liabilities | C12: 13541 | D12: [Balance Sheet]
B13: Total change in working capital | C13: =SUM(C8:C12) -> 7291
B14: Cash provided by operations | C14: =C5+C6+C13 -> 117714
B16: Investments:
B17: Capital expenditures | C17: -44477
B18: plus Acquisitions of companies (net) | C18: -69132
B19: plus Other investing activities | C19: 16639
B20: Cash provided by (used for) investments | C20: =SUM(C17:C19) -> -96970
B22: Financing activities:
B23: Increase (decrease) in short-term debt | C23: 5250
B24: plus Increase (decrease) in long-term debt | C24: -4675
B25: plus Dividends | C25: -21771
B26: plus Issues (repurchases) of stock | C26: -15252
B27: plus Other | C27: -1309
B28: Cash provided by (used for) financing | C28: =SUM(C23:C27) -> -37757
B30: Net increase (decrease) in cash | C30: =C14+C20+C28 -> -17013
B32: Source: Microsoft 10-K FY2024, SEC EDGAR

Sheet Ratios
B1: Ratios — Microsoft Corporation (MSFT)
B2: Metric | C2: Input | D2: Named Range Formula | E2: Named Range
B3: Current year | C3: 2024 | E3: yearCurrent
B4: Start of year | C4: 2023 | D4: yearCurrent - 1 | E4: yearStart
B5: Share price | C5: 446.34 | E5: share_price
B6: Shares outstanding (M) | C6: 7434 | E6: shares_outstanding
B7: Cost of capital | C7: 0.09 | E7: cost_capital
B8: Tax rate | C8: 0.182 | E8: tax_rate
B9: Market capitalization | C9: =C5*C6 -> 3318091.6 | D9: share_price × shares_outstanding | E9: market_capitalization
B11: ─── Start of Year (Prior Year Balance Sheet) ───
B12: Equity (start of year) | C12: ='Balance Sheet'!H18 -> 206223 | D12: BAL_equity_shareholders_2023 | E12: startYear_equity
B13: Inventories (start of year) | C13: ='Balance Sheet'!D7 -> 2500 | D13: BAL_inventories_2023 | E13: startYear_inventory
B14: Receivables (start of year) | C14: ='Balance Sheet'!D6 -> 48688 | D14: BAL_receivables_2023 | E14: startYear_receivables
B15: Total assets (start of year) | C15: ='Balance Sheet'!D20 -> 411976 | D15: BAL_assets_total_2023 | E15: startYear_total_assets
B16: Total capitalization (start of year) | C16: ='Balance Sheet'!H10+'Balance Sheet'!H18 -> 248213 | D16: BAL_debt_long_term_2023 + BAL_equity_shareholders_2023 | E16: startYear_total_capitalization
B18: ─── Current Year (Derived) ───
B19: After-tax operating income | C19: ='Income Statement'!C15+(1-C8)*'Income Statement'!C11 -> 88136 | D19: INC_net + (1−tax_rate) × INC_interest_expense | E19: currentYear_after_tax_operating_income
B20: Average daily sales | C20: ='Income Statement'!C4/365 -> 671.56712 | D20: INC_sales / 365 | E20: currentYear_daily_sales_average
B21: Book value of equity | C21: ='Balance Sheet'!G18 -> 268477 | D21: BAL_equity_shareholders_2024 | E21: currentYear_equity
B22: Cash + Mktable securities | C22: ='Balance Sheet'!C5 -> 75543 | D22: BAL_cash_marketable_securities_2024 | E22: currentYear_cash_marketable_securities
B23: Current assets | C23: ='Balance Sheet'!C9 -> 159734 | D23: BAL_assets_current_2024 | E23: currentYear_assets_current
B24: Current liabilities | C24: ='Balance Sheet'!G8 -> 125286 | D24: BAL_liabilities_current_2024 | E24: currentYear_liabilities_current
B25: Daily COGS | C25: ='Income Statement'!C5/365 -> 203.05205 | D25: INC_cost_goods_sold / 365 | E25: currentYear_cost_goods_sold_daily
B26: Long-term debt | C26: ='Balance Sheet'!G10 -> 42688 | D26: BAL_debt_long_term_2024 | E26: currentYear_debt_long_term
B27: Net working capital | C27: ='Balance Sheet'!C9-'Balance Sheet'!G8 -> 34448 | D27: BAL_assets_current_2024 − BAL_liabilities_current_2024 | E27: currentYear_working_capital_net
B28: Total assets | C28: ='Balance Sheet'!C20 -> 512163 | D28: BAL_assets_total_2024 | E28: currentYear_assets_total
B29: Total capitalization | C29: ='Balance Sheet'!G10+'Balance Sheet'!G18 -> 311165 | D29: BAL_debt_long_term_2024 + BAL_equity_shareholders_2024 | E29: currentYear_total_capitalization
B30: Total liabilities | C30: ='Balance Sheet'!G13 -> 243686 | D30: BAL_liabilities_total_2024 | E30: currentYear_liabilities_total
B32: ─── Mixed Year (Averages) ───
B33: Average equity | C33: =AVERAGE(C12,C21) -> 237350 | D33: AVERAGE(startYear_equity, currentYear_equity) | E33: avg_equity
B34: Average total assets | C34: =AVERAGE(C15,C28) -> 462069.5 | D34: AVERAGE(startYear_total_assets, currentYear_assets_total) | E34: avg_total_assets
B35: Average total capitalization | C35: =AVERAGE(C16,C29) -> 279689 | D35: AVERAGE(startYear_total_capitalization, currentYear_total_capitalization) | E35: avg_total_capitalization
B36: Long-term debt + Equity | C36: =C26+C21 -> 311165 | D36: currentYear_debt_long_term + currentYear_equity | E36: debt_long_term_equity
B39: Ratio | C39: Output (Filled In) | D39: Named Range Formula (reference) | E39: Named Range
B40: Performance
B41: Market value added (MVA) | C41: =C9-C21 -> 3049614.6 | D41: market_capitalization − currentYear_equity
B42: Market-to-book ratio | C42: =C9/C21 -> 12.358942 | D42: market_capitalization / currentYear_equity
B43: Economic value added (EVA) | C43: =C19-(C7*C16) -> 65796.83 | D43: currentYear_after_tax_operating_income − (cost_capital × startYear_total_capitalization)
B45: Profitability
B46: Return on assets (ROA) | C46: =C19/C15 -> 0.21393479 | D46: currentYear_after_tax_operating_income / startYear_total_assets
...

Sheet Notes
B1: Notes & Assumptions — Microsoft Corporation (MSFT)
B3: Company: | C3: Microsoft Corporation
B4: Ticker: | C4: MSFT
B5: Industry: | C5: Technology – Cloud Computing, Software & AI
B6: Fiscal Year (current): | C6: FY2024 (Jun 30, 2024)
B7: Fiscal Year (prior): | C7: FY2023 (Jun 30, 2023)
B8: Data Source: | C8: Microsoft 10-K FY2024, SEC EDGAR
B9: Units: | C9: All figures in millions of US dollars unless otherwise noted.
B10: Tax Rate: | C10: 18.2% — effective rate (Taxes $19,651M ÷ EBT $107,787M); adjust to 21% statutory if preferred
B11: Cost of Capital: | C11: 9.0% — estimated WACC; students may refine using CAPM + class methodology
B12: Share Price: | C12: $446.34 — closing price on Jun 28, 2024 (fiscal year end)
B13: Shares Outstanding: | C13: 7,434M shares (as of Jun 30, 2024)
B15: BUS-314 Project Use: | C15: This workbook provides real financial statement data for the Accounting & Performance Ratios project.
... B20: AI Usage: | C20: [Document any AI tools used and how they were applied — required per course AI guidelines]
